Workbook

Sheet Protocole
A2: Choix de la formulation de l'électrolyte
A3: Mélanger les masses de solides :
E4: masse à introduire dans le mélange
A5: Formulation n° | B5: 1 | C5: Ciment | D5: =LOOKUP(Protocole!B$5,'Recettes électrolyte'!$C$5:$H$5,'Recettes électrolyte'!C6) -> 25 | E5: =B$6*D5/100 -> 10
A6: Masse mélange (g) | B6: 40 | C6: Sable | D6: =LOOKUP(Protocole!B$5,'Recettes électrolyte'!$C$5:$H$5,'Recettes électrolyte'!C7) -> 36 | E6: =B$6*D6/100 -> 14.4
A7: Hauteur du mélange t=0 (mm) | B7: 35 | C7: Gypse | D7: =LOOKUP(Protocole!B$5,'Recettes électrolyte'!$C$5:$H$5,'Recettes électrolyte'!C8) -> 1 | E7: =B$6*D7/100 -> 0.4
A8: Masse volumique (g/cm3) | B8: =B6/(PI()*4*B7/10) -> 0.90945682 | C8: Aluminium | D8: =LOOKUP(Protocole!B$5,'Recettes électrolyte'!$C$5:$H$5,'Recettes électrolyte'!C9) -> 1 | E8: =B$6*D8/100 -> 0.4
A9: Masse volumique corrigée après séchage | C9: Chaux | D9: =LOOKUP(Protocole!B$5,'Recettes électrolyte'!$C$5:$H$5,'Recettes électrolyte'!C10) -> 1 | E9: =B$6*D9/100 -> 0.4
C10: Methylcellulose | D10: =LOOKUP(Protocole!B$5,'Recettes électrolyte'!$C$5:$H$5,'Recettes électrolyte'!C11) -> 1 | E10: =B$6*D10/100 -> 0.4
A11: Bien mélanger puis ajouter l'eau juste quand tout est prêt
C12: Eau | D12: =LOOKUP(Protocole!B$5,'Recettes électrolyte'!$C$5:$H$5,'Recettes électrolyte'!C12) -> 35 | E12: =B$6*D12/100 -> 14
A14: Mesure du coéfficient d'expansion libre
C15: (mm)
A16: Linitiale | B16: L0 = | C16: 45 | D16: mesure de la hauteur de mélange avant expansion
B17: Δlibre | C17: 70 | D17: mesure de la hauteur de mélange après expansion
A18: Lfinale | B18: L0 + Δlibre = | C18: =C16+C17 -> 115
A19: αlibre | B19: =(C18-C16)/C16 -> 1.5555556
A20: Porosité libre (%v) | B20: =B19/(B19+1)*100 -> 60.869565
A21: Calcul bridage des échantillons
A23: Porosité bridé (%v) | B23: 10 | C23: SECURITE PMAX | I23: Porosité visée par Paul
A24: αbridé | B24: =(B23/100)/(1-B23/100) -> 0.11111111 | I24: 10 | J24: 15
A25: Birdage d'expansion β (%) | B25: =(1-B24/B19)*100 -> 92.857143 | I25: 20 | J25: 30
A26: Hydratation maxi (%) | B26: =B24*1/(B24*1+B8)*100 -> 10.887184 | D26: masse d'eau / masse totale | I26: 30 | J26: 45
I27: 40 | J27: 60
A28: Fabrication des échantillons bridés
A29: Nb de Cylindres de 20mm | B29: 8 | C29: Volume de cylindres de 20mm X 50 (cm3) | D29: 15.7 | E29: 15.7
A30: Nb de Cylindres de 40mm | B30: 0 | C30: Volume de cylindres de 40mm (cm3) | D30: 69.11
A31: Nb demi-capteurs de 40mm | B31: 0 | C31: Volume demi-capteurs de 40mm (cm3) | D31: 66.6
A32: Volume total d'électrolyte expansé (cm3) | B32: =B29*D29+B30*D30+B31*D31 -> 125.6
A33: Volume total d'électrolyte avant expansion (cm3) | B33: =B32*(1-B23/100) -> 113.04
A34: Coéfficient de sécurité (%) | B34: 15
A36: Masse de mélange à préparer (g) | B36: =B33*B8/(1-B34/100) -> 120.94706
A37: Masse de mélange à preparer sans coeff de sécurité | B37: =B33*B8 -> 102.805
A38: Masse de mélange à mettre dans les demi-capteur (g) | B38: =B37*((B31*D31)/B32) -> 0 | C38: Masse de mélange à mettre dans un demi-capteur (g) | D38: =B38/B31 -> #DIV/0!
A39: Masse de mélange à mettre dans les cylindre 40mm (g) | B39: =B37*((B30*D30/B32)) -> 0 | C39: Masse de mélange à mettre dans un cylindre 40mm (g) | D39: =B39/B30 -> #DIV/0!
A40: Masse de mélange à mettre dans les cylindre 20mm (g) | B40: =(B37*(B29*D29)/B32) -> 102.805 | C40: Masse de mélange à mettre dans un cylindre 20mm (g) | D40: =B40/B29 -> 12.850625
B41: =SUM(B38:B40) -> 102.805
C43: masse à introduire dans le mélange
B44: Ciment | C44: =B$36*D5/100 -> 30.236764
B45: Sable | C45: =B$36*D6/100 -> 43.540941
...

Sheet Données
B3: Volume de mélange initial pour mesure expansion libre (cm3) | C3: 36.7
B4: Volume de cylindres de 20mm (cm3) | C4: 17.28
B5: Volume de cylindres de 40mm (cm3) | C5: 69.11
B6: Volume demi-capteurs de 40mm (cm3) | C6: 66.6

Sheet Recettes électrolyte
B5: Formulation | C5: 1 | D5: 2 | E5: 3 | F5: 4 | G5: 5 | H5: 6
B6: Ciment | C6: 25 | D6: =C6-1 -> 24
B7: Sable | C7: 36 | D7: =C7-1 -> 35
B8: Gypse | C8: 1 | D8: =C8-1 -> 0
B9: Aluminium | C9: 1 | D9: =C9-1 -> 0
B10: Chaux | C10: 1 | D10: =C10-1 -> 0
B11: Methylcellulose | C11: 1 | D11: =C11-1 -> 0
B12: Eau | C12: 35 | D12: 41
C13: =SUM(C6:C12) -> 100 | D13: =SUM(D6:D12) -> 100
