Workbook

Sheet Protocole pour cylindre de 40mm
A1: ENREGISTRER CE FICHIER POUR CHAQUE FABRICATION
A3: Choix de la formulation de l'électrolyte
A4: Mélanger les masses de solides suivante pour mesurées le αlibre
B5: Cylindre diam=40mm | D5: %massique dans le mélange | E5: masse (g) à introduire dans le mélange
A6: Formulation n° | B6: 1 | C6: Ciment | D6: =LOOKUP('Protocole pour cylindre de 40mm'!B$6,'Recettes électrolyte'!$C$5:$H$5,'Recettes électrolyte'!C6) -> 25 | E6: =B$7*D6/100 -> 25
A7: Masse mélange (g) | B7: 100 | C7: Sable | D7: =LOOKUP('Protocole pour cylindre de 40mm'!B$6,'Recettes électrolyte'!$C$5:$H$5,'Recettes électrolyte'!C7) -> 36 | E7: =B$7*D7/100 -> 36
A8: Hauteur du mélange t=0 (mm) | B8: 35 | C8: Gypse | D8: =LOOKUP('Protocole pour cylindre de 40mm'!B$6,'Recettes électrolyte'!$C$5:$H$5,'Recettes électrolyte'!C8) -> 1 | E8: =B$7*D8/100 -> 1
A9: Masse volumique (g/cm3) | B9: =B7/(PI()*4*B8/10) -> 2.273642 | C9: Aluminium | D9: =LOOKUP('Protocole pour cylindre de 40mm'!B$6,'Recettes électrolyte'!$C$5:$H$5,'Recettes électrolyte'!C9) -> 1 | E9: =B$7*D9/100 -> 1
A10: Masse volumique corrigée après séchage | C10: Chaux | D10: =LOOKUP('Protocole pour cylindre de 40mm'!B$6,'Recettes électrolyte'!$C$5:$H$5,'Recettes électrolyte'!C10) -> 1 | E10: =B$7*D10/100 -> 1
C11: Methylcellulose | D11: =LOOKUP('Protocole pour cylindre de 40mm'!B$6,'Recettes électrolyte'!$C$5:$H$5,'Recettes électrolyte'!C11) -> 1 | E11: =B$7*D11/100 -> 1
A12: Bien mélanger puis ajouter l'eau juste quand tout est prêt
C13: Eau | D13: =LOOKUP('Protocole pour cylindre de 40mm'!B$6,'Recettes électrolyte'!$C$5:$H$5,'Recettes électrolyte'!C12) -> 35 | E13: =B$7*D13/100 -> 35
A15: Mesure du coéfficient d'expansion libre dans un tube de même diamètre que le capteur final
C16: (mm)
A17: Linitiale | B17: L0 = | C17: =B8 -> 35 | D17: mesure de la hauteur de mélange avant expansion
B18: Δlibre | C18: =C19-C17 -> 35
A19: Lfinale | B19: L0 + Δlibre = | C19: 70 | D19: mesure de la hauteur de mélange après expansion
A20: αlibre | B20: =C18/C17 -> 1
A21: Porosité libre (%v) | B21: =B20/(B20+1)*100 -> 50
A22: Calcul bridage des échantillons
A24: Porosité bridé (%v) | B24: 10 | C24: SECURITE PMAX
A25: αbridé | B25: =(B24/100)/(1-B24/100) -> 0.11111111
A26: Birdage d'expansion β (%) | B26: =(1-B25/B20)*100 -> 88.888889
A27: Hydratation maxi (%) | B27: =B25*1/(B25*1+B9)*100 -> 4.659229 | D27: masse d'eau / masse totale
A29: Fabrication des échantillons bridés
A30: Nb de Cylindres de 20m | B30: 2 | C30: Volume de cylindres de 20mm L=65mm (cm3) | D30: 20.4
A31: Nb de Cylindres de 40mm | B31: 0 | C31: Volume de cylindres diam=40mm L=100mm (cm3) | D31: 125.6
A32: Nb demi-capteurs de 40mm | B32: 0 | C32: Volume demi-capteurs diam=40mm L=55mm(cm3) | D32: 69.11
A33: Volume total d'électrolyte expansé (cm3) | B33: =B30*D30+B31*D31+B32*D32 -> 40.8
A34: Volume total d'électrolyte avant expansion (cm3) | B34: =B33*(1-B24/100) -> 36.72
A35: Coéfficient de sécurité (%) | B35: 15
A37: Masse de mélange à préparer (g) | B37: =B34*B9/(1-B35/100) -> 98.221336
A38: Masse de mélange à preparer sans coeff de sécurité | B38: =B34*B9 -> 83.488136
A39: Masse de mélange à mettre dans les demi-capteur (g) | B39: =B38*((B32*D32)/B33) -> 0 | C39: Masse de mélange à mettre dans un demi-capteur (g) | D39: =B39/B32 -> #DIV/0!
A40: Masse de mélange à mettre dans les cylindre 40mm (g) | B40: =B38*((B31*D31/B33)) -> 0 | C40: Masse de mélange à mettre dans un cylindre 40mm (g) | D40: =B40/B31 -> #DIV/0!
A41: Masse de mélange à mettre dans les cylindre 20mm (g) | B41: =(B38*(B30*D30)/B33) -> 83.488136 | C41: Masse de mélange à mettre dans un cylindre 20mm (g) | D41: =B41/B30 -> 41.744068
B42: =SUM(B39:B41) -> 83.488136
C44: masse à introduire dans le mélange
B45: Ciment | C45: =B$37*D6/100 -> 24.555334
B46: Sable | C46: =B$37*D7/100 -> 35.359681
...

Sheet Données
B3: Volume de mélange initial pour mesure expansion libre (cm3) | C3: 36.7
B4: Volume de cylindres de 20mm (cm3) | C4: 17.28
B5: Volume de cylindres de 40mm (cm3) | C5: 69.11
B6: Volume demi-capteurs de 40mm (cm3) | C6: 66.6

Sheet Recettes électrolyte
B5: Formulation | C5: 1 | D5: 2 | E5: 3 | F5: 4 | G5: 5 | H5: 6
B6: Ciment | C6: 25 | D6: =C6-1 -> 24
B7: Sable | C7: 36 | D7: =C7-1 -> 35
B8: Gypse | C8: 1 | D8: =C8-1 -> 0
B9: Aluminium | C9: 1 | D9: =C9-1 -> 0
B10: Chaux | C10: 1 | D10: =C10-1 -> 0
B11: Methylcellulose | C11: 1 | D11: =C11-1 -> 0
B12: Eau | C12: 35 | D12: 41
C13: =SUM(C6:C12) -> 100 | D13: =SUM(D6:D12) -> 100
